2022-09-20 13:35:56,323 we are inside the info main log root INFO
2022-09-20 13:35:56,323 we are inside the error main log root ERROR
2022-09-20 13:35:56,324 we are inside the warning main log root WARNING
2022-09-20 13:36:12,251 we are inside dataframe root INFO
2022-09-20 13:36:12,254 error has occured root ERROR
2022-09-20 13:36:12,255 [Errno 2] No such file or directory: 'C:\\Users\\Sharanya\\OneDrive\\Desktop\\mushrooms.csv' root ERROR
Traceback (most recent call last):
  File "C:\Users\Admin\AppData\Local\Temp\ipykernel_844\3616745588.py", line 3, in <cell line: 1>
    df=pd.read_csv(r"C:\Users\Sharanya\OneDrive\Desktop\mushrooms.csv")
  File "C:\Users\Admin\anaconda3\lib\site-packages\pandas\util\_decorators.py", line 311, in wrapper
    return func(*args, **kwargs)
  File "C:\Users\Admin\anaconda3\lib\site-packages\pandas\io\parsers\readers.py", line 680, in read_csv
    return _read(filepath_or_buffer, kwds)
  File "C:\Users\Admin\anaconda3\lib\site-packages\pandas\io\parsers\readers.py", line 575, in _read
    parser = TextFileReader(filepath_or_buffer, **kwds)
  File "C:\Users\Admin\anaconda3\lib\site-packages\pandas\io\parsers\readers.py", line 933, in __init__
    self._engine = self._make_engine(f, self.engine)
  File "C:\Users\Admin\anaconda3\lib\site-packages\pandas\io\parsers\readers.py", line 1217, in _make_engine
    self.handles = get_handle(  # type: ignore[call-overload]
  File "C:\Users\Admin\anaconda3\lib\site-packages\pandas\io\common.py", line 789, in get_handle
    handle = open(
FileNotFoundError: [Errno 2] No such file or directory: 'C:\\Users\\Sharanya\\OneDrive\\Desktop\\mushrooms.csv'
2022-09-20 13:36:43,392 we are inside dataframe root INFO
2022-09-20 13:36:43,396 error has occured root ERROR
2022-09-20 13:36:43,396 [Errno 2] No such file or directory: 'mushrooms.csv' root ERROR
Traceback (most recent call last):
  File "C:\Users\Admin\AppData\Local\Temp\ipykernel_844\4197559271.py", line 3, in <cell line: 1>
    df=pd.read_csv(r"mushrooms.csv")
  File "C:\Users\Admin\anaconda3\lib\site-packages\pandas\util\_decorators.py", line 311, in wrapper
    return func(*args, **kwargs)
  File "C:\Users\Admin\anaconda3\lib\site-packages\pandas\io\parsers\readers.py", line 680, in read_csv
    return _read(filepath_or_buffer, kwds)
  File "C:\Users\Admin\anaconda3\lib\site-packages\pandas\io\parsers\readers.py", line 575, in _read
    parser = TextFileReader(filepath_or_buffer, **kwds)
  File "C:\Users\Admin\anaconda3\lib\site-packages\pandas\io\parsers\readers.py", line 933, in __init__
    self._engine = self._make_engine(f, self.engine)
  File "C:\Users\Admin\anaconda3\lib\site-packages\pandas\io\parsers\readers.py", line 1217, in _make_engine
    self.handles = get_handle(  # type: ignore[call-overload]
  File "C:\Users\Admin\anaconda3\lib\site-packages\pandas\io\common.py", line 789, in get_handle
    handle = open(
FileNotFoundError: [Errno 2] No such file or directory: 'mushrooms.csv'
2022-09-20 13:37:45,881 we are inside dataframe root INFO
2022-09-20 13:37:45,888 error has occured root ERROR
2022-09-20 13:37:45,888 [Errno 22] Invalid argument: '\u202aC:\\Users\\Admin\\Desktop\\mushrooms.csv' root ERROR
Traceback (most recent call last):
  File "C:\Users\Admin\AppData\Local\Temp\ipykernel_844\791941922.py", line 3, in <cell line: 1>
    df=pd.read_csv(r"\u202aC:\Users\Admin\Desktop\mushrooms.csv")
  File "C:\Users\Admin\anaconda3\lib\site-packages\pandas\util\_decorators.py", line 311, in wrapper
    return func(*args, **kwargs)
  File "C:\Users\Admin\anaconda3\lib\site-packages\pandas\io\parsers\readers.py", line 680, in read_csv
    return _read(filepath_or_buffer, kwds)
  File "C:\Users\Admin\anaconda3\lib\site-packages\pandas\io\parsers\readers.py", line 575, in _read
    parser = TextFileReader(filepath_or_buffer, **kwds)
  File "C:\Users\Admin\anaconda3\lib\site-packages\pandas\io\parsers\readers.py", line 933, in __init__
    self._engine = self._make_engine(f, self.engine)
  File "C:\Users\Admin\anaconda3\lib\site-packages\pandas\io\parsers\readers.py", line 1217, in _make_engine
    self.handles = get_handle(  # type: ignore[call-overload]
  File "C:\Users\Admin\anaconda3\lib\site-packages\pandas\io\common.py", line 789, in get_handle
    handle = open(
OSError: [Errno 22] Invalid argument: '\u202aC:\\Users\\Admin\\Desktop\\mushrooms.csv'
2022-09-20 15:07:03,427 we are inside the info main log root INFO
2022-09-20 15:07:03,430 we are inside the error main log root ERROR
2022-09-20 15:07:03,430 we are inside the warning main log root WARNING
2022-09-20 15:07:05,602 we are inside dataframe root INFO
2022-09-20 15:07:05,605 error has occured root ERROR
2022-09-20 15:07:05,605 [Errno 22] Invalid argument: '\u202aC:\\Users\\Admin\\Desktop\\mushrooms.csv' root ERROR
Traceback (most recent call last):
  File "C:\Users\Admin\AppData\Local\Temp\ipykernel_4300\791941922.py", line 3, in <cell line: 1>
    df=pd.read_csv(r"\u202aC:\Users\Admin\Desktop\mushrooms.csv")
  File "C:\Users\Admin\anaconda3\lib\site-packages\pandas\util\_decorators.py", line 311, in wrapper
    return func(*args, **kwargs)
  File "C:\Users\Admin\anaconda3\lib\site-packages\pandas\io\parsers\readers.py", line 680, in read_csv
    return _read(filepath_or_buffer, kwds)
  File "C:\Users\Admin\anaconda3\lib\site-packages\pandas\io\parsers\readers.py", line 575, in _read
    parser = TextFileReader(filepath_or_buffer, **kwds)
  File "C:\Users\Admin\anaconda3\lib\site-packages\pandas\io\parsers\readers.py", line 933, in __init__
    self._engine = self._make_engine(f, self.engine)
  File "C:\Users\Admin\anaconda3\lib\site-packages\pandas\io\parsers\readers.py", line 1217, in _make_engine
    self.handles = get_handle(  # type: ignore[call-overload]
  File "C:\Users\Admin\anaconda3\lib\site-packages\pandas\io\common.py", line 789, in get_handle
    handle = open(
OSError: [Errno 22] Invalid argument: '\u202aC:\\Users\\Admin\\Desktop\\mushrooms.csv'
2022-09-20 15:47:57,734 we are inside the info main log root INFO
2022-09-20 15:47:57,735 we are inside the error main log root ERROR
2022-09-20 15:47:57,735 we are inside the warning main log root WARNING
2022-09-20 15:47:59,195 we are inside dataframe root INFO
2022-09-20 15:47:59,198 error has occured root ERROR
2022-09-20 15:47:59,198 [Errno 22] Invalid argument: '\u202aC:\\Users\\Admin\\Desktop\\mushrooms.csv' root ERROR
Traceback (most recent call last):
  File "C:\Users\Admin\AppData\Local\Temp\ipykernel_2428\791941922.py", line 3, in <cell line: 1>
    df=pd.read_csv(r"\u202aC:\Users\Admin\Desktop\mushrooms.csv")
  File "C:\Users\Admin\anaconda3\lib\site-packages\pandas\util\_decorators.py", line 311, in wrapper
    return func(*args, **kwargs)
  File "C:\Users\Admin\anaconda3\lib\site-packages\pandas\io\parsers\readers.py", line 680, in read_csv
    return _read(filepath_or_buffer, kwds)
  File "C:\Users\Admin\anaconda3\lib\site-packages\pandas\io\parsers\readers.py", line 575, in _read
    parser = TextFileReader(filepath_or_buffer, **kwds)
  File "C:\Users\Admin\anaconda3\lib\site-packages\pandas\io\parsers\readers.py", line 933, in __init__
    self._engine = self._make_engine(f, self.engine)
  File "C:\Users\Admin\anaconda3\lib\site-packages\pandas\io\parsers\readers.py", line 1217, in _make_engine
    self.handles = get_handle(  # type: ignore[call-overload]
  File "C:\Users\Admin\anaconda3\lib\site-packages\pandas\io\common.py", line 789, in get_handle
    handle = open(
OSError: [Errno 22] Invalid argument: '\u202aC:\\Users\\Admin\\Desktop\\mushrooms.csv'
2022-09-20 16:01:23,508 we are inside the info main log root INFO
2022-09-20 16:01:23,510 we are inside the error main log root ERROR
2022-09-20 16:01:23,511 we are inside the warning main log root WARNING
2022-09-20 16:01:23,523 we are inside dataframe root INFO
2022-09-20 16:01:23,523 error has occured root ERROR
2022-09-20 16:01:23,523 [Errno 22] Invalid argument: '\u202aC:\\Users\\Admin\\Desktop\\mushrooms.csv' root ERROR
Traceback (most recent call last):
  File "C:\Users\Admin\AppData\Local\Temp\ipykernel_2428\791941922.py", line 3, in <cell line: 1>
    df=pd.read_csv(r"\u202aC:\Users\Admin\Desktop\mushrooms.csv")
  File "C:\Users\Admin\anaconda3\lib\site-packages\pandas\util\_decorators.py", line 311, in wrapper
    return func(*args, **kwargs)
  File "C:\Users\Admin\anaconda3\lib\site-packages\pandas\io\parsers\readers.py", line 680, in read_csv
    return _read(filepath_or_buffer, kwds)
  File "C:\Users\Admin\anaconda3\lib\site-packages\pandas\io\parsers\readers.py", line 575, in _read
    parser = TextFileReader(filepath_or_buffer, **kwds)
  File "C:\Users\Admin\anaconda3\lib\site-packages\pandas\io\parsers\readers.py", line 933, in __init__
    self._engine = self._make_engine(f, self.engine)
  File "C:\Users\Admin\anaconda3\lib\site-packages\pandas\io\parsers\readers.py", line 1217, in _make_engine
    self.handles = get_handle(  # type: ignore[call-overload]
  File "C:\Users\Admin\anaconda3\lib\site-packages\pandas\io\common.py", line 789, in get_handle
    handle = open(
OSError: [Errno 22] Invalid argument: '\u202aC:\\Users\\Admin\\Desktop\\mushrooms.csv'
2022-09-20 16:01:23,663 we are expanding display to see more columns root INFO
2022-09-20 16:01:23,733 we are inside dataframe root INFO
2022-09-20 16:01:23,733 error has occured root ERROR
2022-09-20 16:01:23,733 [Errno 2] No such file or directory: 'C:\\Users\\Sharanya\\OneDrive\\Desktop\\mushrooms.csv' root ERROR
Traceback (most recent call last):
  File "C:\Users\Admin\AppData\Local\Temp\ipykernel_2428\1782477082.py", line 3, in <cell line: 1>
    df=pd.read_csv(r"C:\Users\Sharanya\OneDrive\Desktop\mushrooms.csv")
  File "C:\Users\Admin\anaconda3\lib\site-packages\pandas\util\_decorators.py", line 311, in wrapper
    return func(*args, **kwargs)
  File "C:\Users\Admin\anaconda3\lib\site-packages\pandas\io\parsers\readers.py", line 680, in read_csv
    return _read(filepath_or_buffer, kwds)
  File "C:\Users\Admin\anaconda3\lib\site-packages\pandas\io\parsers\readers.py", line 575, in _read
    parser = TextFileReader(filepath_or_buffer, **kwds)
  File "C:\Users\Admin\anaconda3\lib\site-packages\pandas\io\parsers\readers.py", line 933, in __init__
    self._engine = self._make_engine(f, self.engine)
  File "C:\Users\Admin\anaconda3\lib\site-packages\pandas\io\parsers\readers.py", line 1217, in _make_engine
    self.handles = get_handle(  # type: ignore[call-overload]
  File "C:\Users\Admin\anaconda3\lib\site-packages\pandas\io\common.py", line 789, in get_handle
    handle = open(
FileNotFoundError: [Errno 2] No such file or directory: 'C:\\Users\\Sharanya\\OneDrive\\Desktop\\mushrooms.csv'
2022-09-20 16:01:23,753 We are checking the info of complete DataFrame root INFO
2022-09-20 16:01:23,853 We are checking the null values root INFO
2022-09-20 16:01:23,948 Sum the null values in dataset root INFO
2022-09-20 16:01:24,041 we are describing and the columns data root INFO
2022-09-20 16:01:24,117 we are still on categorical data root INFO
2022-09-20 16:01:24,157 We are inside DataFrame function in which it changes categorical values into numerical values by using level and coder method root INFO
2022-09-20 16:01:24,324 We are inside PCA root INFO
2022-09-20 16:01:24,576 finding the sum of 7 components of PCA root INFO
2022-09-20 16:11:07,303 Set the bar plot of accuracy score root INFO
2022-09-20 16:11:09,119 generated new fontManager matplotlib.font_manager INFO
2022-09-20 16:11:17,187 Set the bar plot of accuracy score root INFO
2022-10-02 20:15:01,670 we are inside the info main log root INFO
2022-10-02 20:15:01,679 we are inside the error main log root ERROR
2022-10-02 20:15:01,680 we are inside the warning main log root WARNING
2022-10-02 20:15:03,747 we are inside dataframe root INFO
2022-10-02 20:15:03,753 error has occured root ERROR
2022-10-02 20:15:03,753 [Errno 22] Invalid argument: '\u202aC:\\Users\\Admin\\Desktop\\mushrooms.csv' root ERROR
Traceback (most recent call last):
  File "C:\Users\Admin\AppData\Local\Temp\ipykernel_11576\791941922.py", line 3, in <cell line: 1>
    df=pd.read_csv(r"\u202aC:\Users\Admin\Desktop\mushrooms.csv")
  File "C:\Users\Admin\anaconda3\lib\site-packages\pandas\util\_decorators.py", line 311, in wrapper
    return func(*args, **kwargs)
  File "C:\Users\Admin\anaconda3\lib\site-packages\pandas\io\parsers\readers.py", line 680, in read_csv
    return _read(filepath_or_buffer, kwds)
  File "C:\Users\Admin\anaconda3\lib\site-packages\pandas\io\parsers\readers.py", line 575, in _read
    parser = TextFileReader(filepath_or_buffer, **kwds)
  File "C:\Users\Admin\anaconda3\lib\site-packages\pandas\io\parsers\readers.py", line 933, in __init__
    self._engine = self._make_engine(f, self.engine)
  File "C:\Users\Admin\anaconda3\lib\site-packages\pandas\io\parsers\readers.py", line 1217, in _make_engine
    self.handles = get_handle(  # type: ignore[call-overload]
  File "C:\Users\Admin\anaconda3\lib\site-packages\pandas\io\common.py", line 789, in get_handle
    handle = open(
OSError: [Errno 22] Invalid argument: '\u202aC:\\Users\\Admin\\Desktop\\mushrooms.csv'
2022-10-02 20:15:35,915 we are inside the info main log root INFO
2022-10-02 20:15:35,915 we are inside the error main log root ERROR
2022-10-02 20:15:35,915 we are inside the warning main log root WARNING
